Workbook

Sheet Task-Qustions
A1: TASK
A3: Order_ID | B3: Region | C3: Salesperson | D3: Product | E3: Quantity | F3: Unit_Price | G3: Sales_Date | H3: total | I3: gst amount
A4: 301 | B4: North | C4: Amit | D4: Laptop | E4: 2 | F4: 45000 | G4: 05-01-2025 | H4: {=E4:E9*F4:F9} -> 90000 | I4: =VLOOKUP(D4,[1]Product_Master!$A$2:$C$4,3,FALSE*H4) -> 18
A5: 302 | B5: South | C5: Riya | D5: Mobile | E5: 5 | F5: 15000 | G5: 07-01-2025 | H5: 75000 | I5: =VLOOKUP(D5,[1]Product_Master!$A$2:$C$4,3,FALSE*H5) -> 12
A6: 303 | B6: East | C6: Kunal | D6: Tablet | E6: 3 | F6: 18000 | G6: 10-01-2025 | H6: 54000 | I6: =VLOOKUP(D6,[1]Product_Master!$A$2:$C$4,3,FALSE*H6) -> 12
A7: 304 | B7: West | C7: Neha | D7: Laptop | E7: 1 | F7: 45000 | G7: 12-01-2025 | H7: 45000 | I7: =VLOOKUP(D7,[1]Product_Master!$A$2:$C$4,3,FALSE*H7) -> 18
A8: 305 | B8: North | C8: Amit | D8: Mobile | E8: 4 | F8: 15000 | G8: 15-01-2025 | H8: 60000 | I8: =VLOOKUP(D8,[1]Product_Master!$A$2:$C$4,3,FALSE*H8) -> 12
A9: 306 | B9: South | C9: Riya | D9: Laptop | E9: 2 | F9: 45000 | G9: 18-01-2025 | H9: 90000 | I9: =VLOOKUP(D9,[1]Product_Master!$A$2:$C$4,3,FALSE*H9) -> 18
F11: =SUM(H4:H9) -> 414000
A13: TASK
A14: Product | B14: Category | C14: GST_% | D14: GST_%
A15: Laptop | B15: Electronics | C15: 18 | D15: =C15/100 -> 0.18
A16: Mobile | B16: Electronics | C16: 12 | D16: =C16/100 -> 0.12
A17: Tablet | B17: Electronics | C17: 12 | D17: =C17/100 -> 0.12
C19: =SUM(C15:C17) -> 42
A21: TASK
A22: Student_ID | B22: Name | C22: Maths | D22: Statistics | E22: Excel | F22: Attendance_%
A23: 1 | B23: Rahul | C23: 78 | D23: 82 | E23: 85 | F23: 92
A24: 2 | B24: Sneha | C24: 88 | D24: 91 | E24: 90 | F24: 96
A25: 3 | B25: Arjun | C25: 65 | D25: 70 | E25: 72 | F25: 85
A26: 4 | B26: Pooja | C26: 92 | D26: 89 | E26: 94 | F26: 98
A27: 5 | B27: Vikas | C27: 55 | D27: 60 | E27: 58 | F27: 80
A30: Row Labels | B30: Sum of Excel
A31: Arjun | B31: 72
A32: Pooja | B32: 94
A33: Rahul | B33: 85
A34: Sneha | B34: 90
A35: Vikas | B35: 58
A36: Grand Total | B36: 399

Sheet Answers
A1: 1 | B1: 1. Calculate Total Sales for each order (Quantity × Unit_Price). | L1: 2
A2: ans | B2: Order_ID | C2: Region | D2: Salesperson | E2: Product | F2: Quantity | G2: Unit_Price | H2: Sales_Date | I2: total sale
B3: 301 | C3: North | D3: Amit | E3: Laptop | F3: 2 | G3: 45000 | H3: 05-01-2025 | I3: 90000
B4: 302 | C4: South | D4: Riya | E4: Mobile | F4: 5 | G4: 15000 | H4: 07-01-2025 | I4: 75000
B5: 303 | C5: East | D5: Kunal | E5: Tablet | F5: 3 | G5: 18000 | H5: 10-01-2025 | I5: 54000
B6: 304 | C6: West | D6: Neha | E6: Laptop | F6: 1 | G6: 45000 | H6: 12-01-2025 | I6: 45000
B7: 305 | C7: North | D7: Amit | E7: Mobile | F7: 4 | G7: 15000 | H7: 15-01-2025 | I7: 60000
B8: 306 | C8: South | D8: Riya | E8: Laptop | F8: 2 | G8: 45000 | H8: 18-01-2025 | I8: 90000
A10: 2 | B10: 2. Calculate GST Amount using VLOOKUP from Product_Master. | L10: 2
A11: ans | B11: Order_ID | C11: Region | D11: Salesperson | E11: Product | F11: Quantity | G11: Unit_Price | H11: Sales_Date | I11: gst
B12: 301 | C12: North | D12: Amit | E12: Laptop | F12: 2 | G12: 45000 | H12: 05-01-2025 | I12: 0.18
B13: 302 | C13: South | D13: Riya | E13: Mobile | F13: 5 | G13: 15000 | H13: 07-01-2025 | I13: 0.12
B14: 303 | C14: East | D14: Kunal | E14: Tablet | F14: 3 | G14: 18000 | H14: 10-01-2025 | I14: 0.12
B15: 304 | C15: West | D15: Neha | E15: Laptop | F15: 1 | G15: 45000 | H15: 12-01-2025 | I15: 0.18
B16: 305 | C16: North | D16: Amit | E16: Mobile | F16: 4 | G16: 15000 | H16: 15-01-2025 | I16: 0.12
B17: 306 | C17: South | D17: Riya | E17: Laptop | F17: 2 | G17: 45000 | H17: 18-01-2025 | I17: 0.18
A19: 3 | B19: 3. Find Final Amount payable (Total Sales + GST). | L19: 2
A20: ans | B20: Order_ID | C20: Region | D20: Salesperson | E20: Product | F20: Quantity | G20: Unit_Price | H20: Sales_Date | I20: total sale | J20: gst | K20: ans
B21: 301 | C21: North | D21: Amit | E21: Laptop | F21: 2 | G21: 45000 | H21: 05-01-2025 | I21: 90000 | J21: 0.18 | K21: =I21*J21 -> 16200
B22: 302 | C22: South | D22: Riya | E22: Mobile | F22: 5 | G22: 15000 | H22: 07-01-2025 | I22: 75000 | J22: 0.12 | K22: =I22*J22 -> 9000
B23: 303 | C23: East | D23: Kunal | E23: Tablet | F23: 3 | G23: 18000 | H23: 10-01-2025 | I23: 54000 | J23: 0.12 | K23: =I23*J23 -> 6480
B24: 304 | C24: West | D24: Neha | E24: Laptop | F24: 1 | G24: 45000 | H24: 12-01-2025 | I24: 45000 | J24: 0.18 | K24: =I24*J24 -> 8100
B25: 305 | C25: North | D25: Amit | E25: Mobile | F25: 4 | G25: 15000 | H25: 15-01-2025 | I25: 60000 | J25: 0.12 | K25: =I25*J25 -> 7200
B26: 306 | C26: South | D26: Riya | E26: Laptop | F26: 2 | G26: 45000 | H26: 18-01-2025 | I26: 90000 | J26: 0.18 | K26: =I26*J26 -> 16200
A28: 4 | B28: 4. Find Grand Total of Final Amount. | L28: 2
A29: ans | B29: total sale | C29: grand total
B30: 90000 | C30: 414000
B31: 75000
B32: 54000
B33: 45000
B34: 60000
B35: 90000
A37: 5 | B37: 5. Count total number of orders using COUNTA. | L37: 2
A38: ans | B38: Order_ID | C38: ans
B39: 301 | C39: =COUNTA(B39:B44) -> 6
B40: 302
B41: 303
B42: 304
B43: 305
B44: 306
...
