Workbook

Sheet Instructions
A1: MS Excel Practical Exam
A2: Total Questions: 30
A3: Difficulty Level: Medium
A4: Syllabus: Formulas, Logical Functions, Lookups, INDEX-MATCH, Pivot Tables & Charts, Data Analysis
A5: Attempt all questions using appropriate Excel tools/functions.

Sheet Sales_Data
A1: Order_ID | B1: Region | C1: Salesperson | D1: Product | E1: Quantity | F1: Unit_Price | G1: Sales_Date | H1: total | I1: gst amount
A2: 301 | B2: North | C2: Amit | D2: Laptop | E2: 2 | F2: 45000 | G2: 05-01-2025 | H2: {=E2:E7*F2:F7} -> 90000 | I2: =VLOOKUP(D2,Product_Master!$A$2:$C$4,3,FALSE*H2) -> 18 | L2: Row Labels | M2: Sum of total
A3: 302 | B3: South | C3: Riya | D3: Mobile | E3: 5 | F3: 15000 | G3: 07-01-2025 | H3: 75000 | I3: =VLOOKUP(D3,Product_Master!$A$2:$C$4,3,FALSE*H3) -> 12 | L3: Laptop | M3: 225000
A4: 303 | B4: East | C4: Kunal | D4: Tablet | E4: 3 | F4: 18000 | G4: 10-01-2025 | H4: 54000 | I4: =VLOOKUP(D4,Product_Master!$A$2:$C$4,3,FALSE*H4) -> 12 | L4: Mobile | M4: 135000
A5: 304 | B5: West | C5: Neha | D5: Laptop | E5: 1 | F5: 45000 | G5: 12-01-2025 | H5: 45000 | I5: =VLOOKUP(D5,Product_Master!$A$2:$C$4,3,FALSE*H5) -> 18 | L5: Tablet | M5: 54000
A6: 305 | B6: North | C6: Amit | D6: Mobile | E6: 4 | F6: 15000 | G6: 15-01-2025 | H6: 60000 | I6: =VLOOKUP(D6,Product_Master!$A$2:$C$4,3,FALSE*H6) -> 12 | L6: Grand Total | M6: 414000
A7: 306 | B7: South | C7: Riya | D7: Laptop | E7: 2 | F7: 45000 | G7: 18-01-2025 | H7: 90000 | I7: =VLOOKUP(D7,Product_Master!$A$2:$C$4,3,FALSE*H7) -> 18
F15: =SUM(_xlfn.ANCHORARRAY(H2)) -> 414000

Sheet Product_Master
A1: Product | B1: Category | C1: GST_% | D1: GST_%
A2: Laptop | B2: Electronics | C2: 18 | D2: =C2/100 -> 0.18
A3: Mobile | B3: Electronics | C3: 12 | D3: =C3/100 -> 0.12
A4: Tablet | B4: Electronics | C4: 12 | D4: =C4/100 -> 0.12
C6: =SUM(C2:C4) -> 42

Sheet Student_Marks
A1: Student_ID | B1: Name | C1: Maths | D1: Statistics | E1: Excel | F1: Attendance_%
A2: 1 | B2: Rahul | C2: 78 | D2: 82 | E2: 85 | F2: 92 | H2: {=((C2:E2)/300)*100} -> 26 | I2: 27.333333 | J2: 28.333333
A3: 2 | B3: Sneha | C3: 88 | D3: 91 | E3: 90 | F3: 96 | H3: {=((C3:E3)/300)*100} -> 29.333333 | I3: 30.333333 | J3: 30
A4: 3 | B4: Arjun | C4: 65 | D4: 70 | E4: 72 | F4: 85 | H4: {=((C4:E4)/300)*100} -> 21.666667 | I4: 23.333333 | J4: 24
A5: 4 | B5: Pooja | C5: 92 | D5: 89 | E5: 94 | F5: 98 | H5: {=((C5:E5)/300)*100} -> 30.666667 | I5: 29.666667 | J5: 31.333333
A6: 5 | B6: Vikas | C6: 55 | D6: 60 | E6: 58 | F6: 80 | H6: {=((C6:E6)/300)*100} -> 18.333333 | I6: 20 | J6: 19.333333
A9: Row Labels | B9: Sum of Excel
A10: Arjun | B10: 72
A11: Pooja | B11: 94
A12: Rahul | B12: 85
A13: Sneha | B13: 90
A14: Vikas | B14: 58
A15: Grand Total | B15: 399

Sheet Questions
B1: 1. Calculate Total Sales for each order (Quantity × Unit_Price). | L1: 2
A2: ans | B2: Order_ID | C2: Region | D2: Salesperson | E2: Product | F2: Quantity | G2: Unit_Price | H2: Sales_Date | I2: total sale
B3: 301 | C3: North | D3: Amit | E3: Laptop | F3: 2 | G3: 45000 | H3: 05-01-2025 | I3: =F3*G3 -> 90000
B4: 302 | C4: South | D4: Riya | E4: Mobile | F4: 5 | G4: 15000 | H4: 07-01-2025 | I4: =F4*G4 -> 75000
B5: 303 | C5: East | D5: Kunal | E5: Tablet | F5: 3 | G5: 18000 | H5: 10-01-2025 | I5: =F5*G5 -> 54000
B6: 304 | C6: West | D6: Neha | E6: Laptop | F6: 1 | G6: 45000 | H6: 12-01-2025 | I6: =F6*G6 -> 45000
B7: 305 | C7: North | D7: Amit | E7: Mobile | F7: 4 | G7: 15000 | H7: 15-01-2025 | I7: =F7*G7 -> 60000
B8: 306 | C8: South | D8: Riya | E8: Laptop | F8: 2 | G8: 45000 | H8: 18-01-2025 | I8: =F8*G8 -> 90000
B9: 2. Calculate GST Amount using VLOOKUP from Product_Master. | L9: 2
A10: ans | B10: Order_ID | C10: Region | D10: Salesperson | E10: Product | F10: Quantity | G10: Unit_Price | H10: Sales_Date | I10: gst
B11: 301 | C11: North | D11: Amit | E11: Laptop | F11: 2 | G11: 45000 | H11: 05-01-2025 | I11: =VLOOKUP(E11,Product_Master!$A$1:$D$4,4,FALSE) -> 0.18
B12: 302 | C12: South | D12: Riya | E12: Mobile | F12: 5 | G12: 15000 | H12: 07-01-2025 | I12: =VLOOKUP(E12,Product_Master!$A$1:$D$4,4,FALSE) -> 0.12
B13: 303 | C13: East | D13: Kunal | E13: Tablet | F13: 3 | G13: 18000 | H13: 10-01-2025 | I13: =VLOOKUP(E13,Product_Master!$A$1:$D$4,4,FALSE) -> 0.12
B14: 304 | C14: West | D14: Neha | E14: Laptop | F14: 1 | G14: 45000 | H14: 12-01-2025 | I14: =VLOOKUP(E14,Product_Master!$A$1:$D$4,4,FALSE) -> 0.18
B15: 305 | C15: North | D15: Amit | E15: Mobile | F15: 4 | G15: 15000 | H15: 15-01-2025 | I15: =VLOOKUP(E15,Product_Master!$A$1:$D$4,4,FALSE) -> 0.12
B16: 306 | C16: South | D16: Riya | E16: Laptop | F16: 2 | G16: 45000 | H16: 18-01-2025 | I16: =VLOOKUP(E16,Product_Master!$A$1:$D$4,4,FALSE) -> 0.18
B19: 3. Find Final Amount payable (Total Sales + GST). | L19: 2
A20: ans | B20: Order_ID | C20: Region | D20: Salesperson | E20: Product | F20: Quantity | G20: Unit_Price | H20: Sales_Date | I20: total sale | J20: gst | K20: ans
B21: 301 | C21: North | D21: Amit | E21: Laptop | F21: 2 | G21: 45000 | H21: 05-01-2025 | I21: 90000 | J21: 0.18 | K21: =I21*J21 -> 16200
B22: 302 | C22: South | D22: Riya | E22: Mobile | F22: 5 | G22: 15000 | H22: 07-01-2025 | I22: 75000 | J22: 0.12 | K22: =I22*J22 -> 9000
B23: 303 | C23: East | D23: Kunal | E23: Tablet | F23: 3 | G23: 18000 | H23: 10-01-2025 | I23: 54000 | J23: 0.12 | K23: =I23*J23 -> 6480
B24: 304 | C24: West | D24: Neha | E24: Laptop | F24: 1 | G24: 45000 | H24: 12-01-2025 | I24: 45000 | J24: 0.18 | K24: =I24*J24 -> 8100
B25: 305 | C25: North | D25: Amit | E25: Mobile | F25: 4 | G25: 15000 | H25: 15-01-2025 | I25: 60000 | J25: 0.12 | K25: =I25*J25 -> 7200
B26: 306 | C26: South | D26: Riya | E26: Laptop | F26: 2 | G26: 45000 | H26: 18-01-2025 | I26: 90000 | J26: 0.18 | K26: =I26*J26 -> 16200
B29: 4. Find Grand Total of Final Amount. | L29: 2
A30: ans | B30: total sale | C30: grand total
B31: 90000 | C31: =SUM(B31:B36) -> 414000
B32: 75000
B33: 54000
B34: 45000
B35: 60000
B36: 90000
B38: 5. Count total number of orders using COUNTA. | L38: 2
A39: ans | C39: =COUNTA(Sales_Data!A2:A7) -> 6
B41: 6. Find Region-wise total sales using SUMIF. | L41: 2
A42: ans | B42: North | C42: {=SUMIF(Questions!B42,Sales_Data!B2:B7,_xlfn.ANCHORARRAY(Sales_Data!H2))} -> 90000
C43: 0
C44: 0
C45: 0
C46: 90000
...
